I'm sorry, but an uncaught exception occurred.

While running game code:
  File "game/script.rpy", line 38, in script
    pov "My name is [povName]!"
KeyError: u'povname'

-- Full Traceback ------------------------------------------------------------

Full traceback:
  File "game/script.rpy", line 38, in script
    pov "My name is [povName]!"
  File "/Applications/renpy-7.1.3-sdk/renpy/ast.py", line 715, in execute
    renpy.exports.say(who, what, *args, **kwargs)
  File "/Applications/renpy-7.1.3-sdk/renpy/exports.py", line 1384, in say
    who(what, *args, **kwargs)
  File "/Applications/renpy-7.1.3-sdk/renpy/character.py", line 1158, in __call__
    who = who_pattern.replace("[who]", sub(who))
  File "/Applications/renpy-7.1.3-sdk/renpy/character.py", line 1153, in sub
    return renpy.substitutions.substitute(s, scope=scope, force=force, translate=translate)[0]
  File "/Applications/renpy-7.1.3-sdk/renpy/substitutions.py", line 270, in substitute
    s = formatter.vformat(s, (), kwargs)
  File "/home/tom/ab/renpy-build/tmp/install.linux-x86_64/lib/python2.7/string.py", line 563, in vformat
  File "/home/tom/ab/renpy-build/tmp/install.linux-x86_64/lib/python2.7/string.py", line 585, in _vformat
  File "/home/tom/ab/renpy-build/tmp/install.linux-x86_64/lib/python2.7/string.py", line 646, in get_field
  File "/home/tom/ab/renpy-build/tmp/install.linux-x86_64/lib/python2.7/string.py", line 605, in get_value
KeyError: u'povname'

Darwin-20.3.0-x86_64-i386-64bit
Ren'Py 7.4.2.1292
Where is Love 1.0
Tue Feb 16 02:59:49 2021
